[2024-01-26 15:28:06,427] 20 root - INFO - This is my 1st testing
[2024-01-26 15:28:06,891] 96 werkzeug - INFO - [31m[1mWARNING: This is a development server. Do not use it in a production deployment. Use a production WSGI server instead.[0m
 * Running on all addresses (0.0.0.0)
 * Running on http://127.0.0.1:5000
 * Running on http://172.18.0.12:5000
[2024-01-26 15:28:06,891] 96 werkzeug - INFO - [33mPress CTRL+C to quit[0m
[2024-01-26 15:33:46,929] 96 werkzeug - INFO - 172.18.0.2 - - [26/Jan/2024 15:33:46] "GET / HTTP/1.1" 200 -
[2024-01-26 15:33:46,994] 96 werkzeug - INFO - 172.18.0.2 - - [26/Jan/2024 15:33:46] "[33mGET /favicon.ico HTTP/1.1[0m" 404 -
[2024-01-26 15:33:53,439] 96 werkzeug - INFO - 172.18.0.2 - - [26/Jan/2024 15:33:53] "GET /predict HTTP/1.1" 200 -
[2024-01-26 15:34:32,617] 1414 app - ERROR - Exception on /predict [POST]
Traceback (most recent call last):
  File "/config/workspace/env/lib/python3.8/site-packages/flask/app.py", line 2190, in wsgi_app
    response = self.full_dispatch_request()
  File "/config/workspace/env/lib/python3.8/site-packages/flask/app.py", line 1486, in full_dispatch_request
    rv = self.handle_user_exception(e)
  File "/config/workspace/env/lib/python3.8/site-packages/flask/app.py", line 1484, in full_dispatch_request
    rv = self.dispatch_request()
  File "/config/workspace/env/lib/python3.8/site-packages/flask/app.py", line 1469, in dispatch_request
    return self.ensure_sync(self.view_functions[rule.endpoint])(**view_args)
  File "app.py", line 27, in predict_datapoint
    final_data = get_data_as_dataframe(data)
NameError: name 'get_data_as_dataframe' is not defined
[2024-01-26 15:34:32,619] 96 werkzeug - INFO - 172.18.0.2 - - [26/Jan/2024 15:34:32] "[35m[1mPOST /predict HTTP/1.1[0m" 500 -
